<?xml version="1.0"?>
<robot xmlns:xacro="http://www.ros.org/wiki/xacro" >
    
    <xacro:include filename="inertial_macros.xacro"/>

    <material name="white">
        <color rgba="1.0 1.0 1.0 1.0"/>
    </material>

    <material name="orange">
        <color rgba="1.0 0.3 0.1 1.0"/>
    </material>

    <material name="blue">
        <color rgba="0.2 0.2 1.0 1.0"/>
    </material>

    <material name="black">
        <color rgba="0.0 0.0 0.0 1.0"/>
    </material>
    
    <material name="Gray">
        <color rgba="0.3 0.3 0.3 1.0"/>
    </material>

    <!-- Base Link -->
    <link name="base_link">
        <visual>
            <origin xyz="0.0 0.0 0.0" rpy="0.0 0.0 0.0"/>
            
        </visual>
    </link>

    <joint name="chassis_joint" type="fixed">
        <origin xyz="0.0 0.0 0.0" rpy="0.0 0.0 0.0"/>
        <parent link="base_link"/>
        <child link="chassis"/>
        <axis xyz="0.0 0.0 0.0"/>
        <limit lower="0.0" upper="0.0" effort="0.0" velocity="0.0"/>
    </joint>

    <!-- Chassis Link-->
    <link name="chassis">
        <visual>
            <origin xyz="0.0 0.0 0.01" rpy="0.0 0.0 0.0"/>
            
            <geometry>
                <box size=".3 0.2 0.035"/>
            </geometry>

            <material name="Gray">
                <color rgba="0.3 0.3 0.3 1.0"/>
            </material>
        </visual>

        <collision>
            <origin xyz="0.0 0.0 0.0" rpy="0.0 0.0 0.0"/>
            <geometry>
                <box size="0.3 0.2 0.035"/>
            </geometry>
        </collision>

        <xacro:inertial_box mass = "0.5"  x = "0.3" y = "0.2" z = "0.035">
            <origin xyz="0.0 0.0 0.01" rpy="0.0 0.0 0.0"/>
            
        </xacro:inertial_box>
    </link>

    <gazebo reference = "chassis">
        <material>
            Gazebo/Gray
        </material>
    </gazebo>

    <!--  Front Left Wheel Link-->
    <joint name="front_left_wheel_joint" type="continuous">
        
        <parent link="base_link"/>
        <child link="front_left_wheel"/>
        <origin xyz="0.08 0.118 0.01" rpy="-1.57 0.0 0.0"/>
        <axis xyz="0.0 0.0 -0.1"/>
        
            
    </joint>

    <link name="front_left_wheel">
        <visual>
            
            <geometry>
                <cylinder radius=".035" length="0.035"/>
            </geometry>

            <material name="orange">
                <color rgba="0.0 0.0 0.0 1.0"/>
            </material>
        </visual>

        <collision>
            <geometry>
                <cylinder radius="0.035" length="0.035"/>
            </geometry>
        </collision>

        <xacro:inertial_cylinder mass="0.1" radius="0.035" length="0.035">
            <origin xyz="0.0 0.0 0.0" rpy="0.0 0.0 0.0"/>
        </xacro:inertial_cylinder>

    </link>

    <gazebo reference = "front_left_wheel">
        <material>
            Gazebo/Orange
        </material>
    </gazebo>
    

    <!-- Front Right Wheel Link -->
    <joint name="front_right_wheel_joint" type="continuous">
        
        <parent link="base_link"/>
        <child link="front_right_wheel"/>
        <origin xyz="0.08 -0.118 0.01" rpy="1.57 0.0 0.0"/>
        <axis xyz="0.0 0.0 -0.1"/>
            
    </joint>

    <link name="front_right_wheel">
        <visual>
            
            <geometry>
                <cylinder radius=".035" length="0.035"/>
            </geometry>

            <material name="orange">
                <color rgba="0.0 0.0 0.0 1.0"/>
            </material>
        </visual>

        <collision>
            <geometry>
                <cylinder radius="0.035" length="0.035"/>
            </geometry>
        </collision>

        <xacro:inertial_cylinder mass="0.1" radius="0.035" length="0.035">
            <origin xyz="0.0 0.0 0.0" rpy="0.0 0.0 0.0"/>
        </xacro:inertial_cylinder>

    </link>

    <gazebo reference = "front_right_wheel">
        <material>
            Gazebo/Orange
        </material>
    </gazebo>
    

    <!-- Back Left Wheel Link  -->
    <joint name="back_left_wheel_joint" type="continuous">
        
        <parent link="base_link"/>
        <child link="back_left_wheel"/>

        <origin xyz="-0.08 0.118 0.01" rpy="-1.57 0.0 0.0"/>
        <axis xyz="0.0 0.0 -0.1"/>
            
    </joint>

    <link name="back_left_wheel">
        <visual>
            
            <geometry>
                <cylinder radius=".035" length="0.035"/>
            </geometry>

            <material name="orange">
                <color rgba="0.0 0.0 0.0 1.0"/>
            </material>
        </visual>

        <collision>
            <geometry>
                <cylinder radius="0.035" length="0.035"/>
            </geometry>
        </collision>

        <xacro:inertial_cylinder mass="0.1" radius="0.035" length="0.035">
            <origin xyz="0.0 0.0 0.0" rpy="0.0 0.0 0.0"/>
        </xacro:inertial_cylinder>

    </link>

    <gazebo reference = "back_left_wheel">
        <material>
            Gazebo/Orange
        </material>
    </gazebo>
   

    <!-- Back Right Wheel Link -->
    <joint name="back_right_wheel_joint" type="continuous">
        
        <parent link="base_link"/>
        <child link="back_right_wheel"/>

        <origin xyz="-0.08 -0.118 0.01" rpy="1.57 0.0 0.0"/>
        <axis xyz="0.0 0.0 -0.1"/>
            
    </joint>

    <link name="back_right_wheel">
        <visual>
            
            <geometry>
                <cylinder radius=".035" length="0.035"/>
            </geometry>

            <material name="orange">
                <color rgba="0.0 0.0 0.0 1.0"/>
            </material>
        </visual>

        <collision>
            <geometry>
                <cylinder radius="0.035" length="0.035"/>
            </geometry>
        </collision>

        <xacro:inertial_cylinder mass="0.1" radius="0.035" length="0.035">
            <origin xyz="0.0 0.0 0.0" rpy="0.0 0.0 0.0"/>
        </xacro:inertial_cylinder>

    </link> 

    <gazebo reference = "back_right_wheel">
        <material>
            Gazebo/Orange
        </material>
    </gazebo>
    
    </robot>
